<?xml version="1.0" encoding="utf-8"?>
<!-- This URDF was automatically created by SolidWorks to URDF Exporter! Originally created by Stephen Brawner (brawner@gmail.com) 
     Commit Version: 1.6.0-4-g7f85cfe  Build Version: 1.6.7995.38578
     For more information, please see http://wiki.ros.org/sw_urdf_exporter -->
<robot
  name="robotic_arm">
  <link
    name="base_link">
    <inertial>
      <origin
        xyz="-1.1102E-16 0 0.073876"
        rpy="0 0 0" />
      <mass
        value="17.147" />
      <inertia
        ixx="0.192"
        ixy="-4.9423E-10"
        ixz="-5.4429E-17"
        iyy="0.192"
        iyz="2.0103E-17"
        izz="0.29544" />
    </inertial>
    <visual>
      <origin
        xyz="0 0 0"
        rpy="0 0 0" />
      <geometry>
        <mesh
          filename="package://robotic_arm/meshes/base_link.STL" />
      </geometry>
      <material
        name="">
        <color
          rgba="0.79216 0.81961 0.93333 1" />
      </material>
    </visual>
    <collision>
      <origin
        xyz="0 0 0"
        rpy="0 0 0" />
      <geometry>
        <mesh
          filename="package://robotic_arm/meshes/base_link.STL" />
      </geometry>
    </collision>
  </link>
  <link
    name="link1">
    <inertial>
      <origin
        xyz="-5.65270052987898E-12 -0.094533892766691 7.88580312161002E-11"
        rpy="0 0 0" />
      <mass
        value="3.09046329461168" />
      <inertia
        ixx="0.0262980576865812"
        ixy="-4.70225488404403E-13"
        ixz="5.78426964247605E-05"
        iyy="0.0196320103484557"
        iyz="7.43867953096951E-12"
        izz="0.0253915865728046" />
    </inertial>
    <visual>
      <origin
        xyz="0 0 0"
        rpy="0 0 0" />
      <geometry>
        <mesh
          filename="package://robotic_arm/meshes/link1.STL" />
      </geometry>
      <material
        name="">
        <color
          rgba="1 1 1 1" />
      </material>
    </visual>
    <collision>
      <origin
        xyz="0 0 0"
        rpy="0 0 0" />
      <geometry>
        <mesh
          filename="package://robotic_arm/meshes/link1.STL" />
      </geometry>
    </collision>
  </link>
  <joint
    name="link1_revolute"
    type="revolute">
    <origin
      xyz="0 0 0.405"
      rpy="1.5707963267949 0 -2.76394490191366" />
    <parent
      link="base_link" />
    <child
      link="link1" />
    <axis
      xyz="0 1 0" />
    <limit
      lower="0"
      upper="3.142"
      effort="0"
      velocity="0" />
  </joint>
  <link
    name="link2">
    <inertial>
      <origin
        xyz="5.55111512312578E-16 0.167517809032193 -4.44089209850063E-16"
        rpy="0 0 0" />
      <mass
        value="5.58667658903741" />
      <inertia
        ixx="0.126335373950319"
        ixy="-2.25047998865248E-18"
        ixz="-0.000176634600159667"
        iyy="0.0114008236557685"
        iyz="-3.20896236448742E-17"
        izz="0.129103470333829" />
    </inertial>
    <visual>
      <origin
        xyz="0 0 0"
        rpy="0 0 0" />
      <geometry>
        <mesh
          filename="package://robotic_arm/meshes/link2.STL" />
      </geometry>
      <material
        name="">
        <color
          rgba="0.792156862745098 0.819607843137255 0.933333333333333 1" />
      </material>
    </visual>
    <collision>
      <origin
        xyz="0 0 0"
        rpy="0 0 0" />
      <geometry>
        <mesh
          filename="package://robotic_arm/meshes/link2.STL" />
      </geometry>
    </collision>
  </link>
  <joint
    name="link2_revolute"
    type="revolute">
    <origin
      xyz="0 0 0"
      rpy="0 0 0" />
    <parent
      link="link1" />
    <child
      link="link2" />
    <axis
      xyz="0.0634251661005122 0 -0.997986597257259" />
    <limit
      lower="-1.57"
      upper="1.57"
      effort="0"
      velocity="0" />
  </joint>
  <link
    name="link3">
    <inertial>
      <origin
        xyz="0.174395473981125 0.0384516706727349 0.0111232348782355"
        rpy="0 0 0" />
      <mass
        value="2.82619520285645" />
      <inertia
        ixx="0.00844864895794914"
        ixy="-0.00442959527109717"
        ixz="-0.00106465357356354"
        iyy="0.0275749332622264"
        iyz="-0.000278835988235278"
        izz="0.0250601393266879" />
    </inertial>
    <visual>
      <origin
        xyz="0 0 0"
        rpy="0 0 0" />
      <geometry>
        <mesh
          filename="package://robotic_arm/meshes/link3.STL" />
      </geometry>
      <material
        name="">
        <color
          rgba="0.792156862745098 0.819607843137255 0.933333333333333 1" />
      </material>
    </visual>
    <collision>
      <origin
        xyz="0 0 0"
        rpy="0 0 0" />
      <geometry>
        <mesh
          filename="package://robotic_arm/meshes/link3.STL" />
      </geometry>
    </collision>
  </link>
  <joint
    name="link3_revolute"
    type="revolute">
    <origin
      xyz="0 0.4 0"
      rpy="0 0 -0.0169636090218563" />
    <parent
      link="link2" />
    <child
      link="link3" />
    <axis
      xyz="0.0634160405786047 0.00107586811877688 -0.99798659725726" />
    <limit
      lower="0"
      upper="3.142"
      effort="0"
      velocity="0" />
  </joint>
  <link
    name="link4">
    <inertial>
      <origin
        xyz="-0.0118858896349915 -0.0506456824953578 -0.0697406192943522"
        rpy="0 0 0" />
      <mass
        value="1.80974470730009" />
      <inertia
        ixx="0.00932958069415946"
        ixy="0.0013494372798654"
        ixz="1.98874384850704E-05"
        iyy="0.00259829198759458"
        iyz="-0.000438489662118864"
        izz="0.00938432134538898" />
    </inertial>
    <visual>
      <origin
        xyz="0 0 0"
        rpy="0 0 0" />
      <geometry>
        <mesh
          filename="package://robotic_arm/meshes/link4.STL" />
      </geometry>
      <material
        name="">
        <color
          rgba="0.792156862745098 0.819607843137255 0.933333333333333 1" />
      </material>
    </visual>
    <collision>
      <origin
        xyz="0 0 0"
        rpy="0 0 0" />
      <geometry>
        <mesh
          filename="package://robotic_arm/meshes/link4.STL" />
      </geometry>
    </collision>
  </link>
  <joint
    name="link4_revolute"
    type="revolute">
    <origin
      xyz="0.33669051723305 0.075138823425112 0.0916168806467064"
      rpy="0 -0.37764775167464 0.0169636090218595" />
    <parent
      link="link3" />
    <child
      link="link4" />
    <axis
      xyz="-0.309036699346333 0 -0.95105011353615" />
    <limit
      lower="0"
      upper="-3.142"
      effort="0"
      velocity="0" />
  </joint>
  <link
    name="link5">
    <inertial>
      <origin
        xyz="-0.000635733956954793 -0.000212077273990863 0.02344654214119"
        rpy="0 0 0" />
      <mass
        value="0.190534243496226" />
      <inertia
        ixx="0.00021723232799195"
        ixy="3.2960030899886E-05"
        ixz="-1.99933248330466E-06"
        iyy="0.000129424517463001"
        iyz="-6.66965312608118E-07"
        izz="0.000301904828698227" />
    </inertial>
    <visual>
      <origin
        xyz="0 0 0"
        rpy="0 0 0" />
      <geometry>
        <mesh
          filename="package://robotic_arm/meshes/link5.STL" />
      </geometry>
      <material
        name="">
        <color
          rgba="0.792156862745098 0.819607843137255 0.933333333333333 1" />
      </material>
    </visual>
    <collision>
      <origin
        xyz="0 0 0"
        rpy="0 0 0" />
      <geometry>
        <mesh
          filename="package://robotic_arm/meshes/link5.STL" />
      </geometry>
    </collision>
  </link>
  <joint
    name="link5_revolute"
    type="revolute">
    <origin
      xyz="0.0217512505054844 -0.225430946671694 -0.0806707591650744"
      rpy="1.50080931610212 0.0154073486983046 -2.92525450953042" />
    <parent
      link="link4" />
    <child
      link="link5" />
    <axis
      xyz="-0.0271031214688434 -0.00904142340899337 0.99959175340205" />
    <limit
      lower="0"
      upper="3.142"
      effort="0"
      velocity="0" />
  </joint>
  <link
    name="link6_1">
    <inertial>
      <origin
        xyz="-0.521249947261589 1.14807668502178 0.0360029769263748"
        rpy="0 0 0" />
      <mass
        value="0.116532917792388" />
      <inertia
        ixx="4.06995329663622E-05"
        ixy="6.06060925640919E-06"
        ixz="-1.03759630985349E-05"
        iyy="7.005266679884E-05"
        iyz="3.14045201144727E-06"
        izz="8.45577273716619E-05" />
    </inertial>
    <visual>
      <origin
        xyz="0 0 0"
        rpy="0 0 0" />
      <geometry>
        <mesh
          filename="package://robotic_arm/meshes/link6_1.STL" />
      </geometry>
      <material
        name="">
        <color
          rgba="0.792156862745098 0.819607843137255 0.933333333333333 1" />
      </material>
    </visual>
    <collision>
      <origin
        xyz="0 0 0"
        rpy="0 0 0" />
      <geometry>
        <mesh
          filename="package://robotic_arm/meshes/link6_1.STL" />
      </geometry>
    </collision>
  </link>
  <joint
    name="link6_1_prismatic"
    type="prismatic">
    <origin
      xyz="0.91471 0.3654 0.76296"
      rpy="-1.5116 -1.3256 -2.8152" />
    <parent
      link="link5" />
    <child
      link="link6_1" />
    <axis
      xyz="-0.0010759 -0.063416 -0.99799" />
    <limit
      lower="0"
      upper="0.03"
      effort="0"
      velocity="0" />
  </joint>
  <link
    name="link6_2">
    <inertial>
      <origin
        xyz="-0.521359713734869 -0.341606602859672 0.0858175618375348"
        rpy="0 0 0" />
      <mass
        value="0.116532917792388" />
      <inertia
        ixx="4.0742646271086E-05"
        ixy="-7.32651075997336E-06"
        ixz="-9.6204923082993E-06"
        iyy="6.94944406123816E-05"
        iyz="-1.23562139946212E-06"
        izz="8.50728402533904E-05" />
    </inertial>
    <visual>
      <origin
        xyz="0 0 0"
        rpy="0 0 0" />
      <geometry>
        <mesh
          filename="package://robotic_arm/meshes/link6_2.STL" />
      </geometry>
      <material
        name="">
        <color
          rgba="0.792156862745098 0.819607843137255 0.933333333333333 1" />
      </material>
    </visual>
    <collision>
      <origin
        xyz="0 0 0"
        rpy="0 0 0" />
      <geometry>
        <mesh
          filename="package://robotic_arm/meshes/link6_2.STL" />
      </geometry>
    </collision>
  </link>
  <joint
    name="link6_2_prismatic"
    type="prismatic">
    <origin
      xyz="0.203547969834237 0.0536399403068246 0.569409308513323"
      rpy="1.62995489797154 -1.32563166552103 -2.81517539067378" />
    <parent
      link="link5" />
    <child
      link="link6_2" />
    <axis
      xyz="-0.00107586811877956 0.0634160405786034 0.997986597257259" />
    <limit
      lower="-0.03"
      upper="0"
      effort="0"
      velocity="0" />
  </joint>

  <transmission name="link1_trans">
      <type>transmission_interface/SimpleTransmission</type>
      <joint name="link1_revolute">
      <hardwareInterface>hardware_interface/PositionJointInterface</hardwareInterface>
      </joint>
      <actuator name="link1_motor">
      <hardwareInterface>hardware_interface/PositionJointInterface</hardwareInterface>
      <mechanicalReduction>1</mechanicalReduction>
      </actuator>
  </transmission>

  <transmission name="link2_trans">
      <type>transmission_interface/SimpleTransmission</type>
      <joint name="link2_revolute">
      <hardwareInterface>hardware_interface/PositionJointInterface</hardwareInterface>
      </joint>
      <actuator name="link2_motor">
      <hardwareInterface>hardware_interface/PositionJointInterface</hardwareInterface>
      <mechanicalReduction>1</mechanicalReduction>
      </actuator>
  </transmission>

  <transmission name="link3_trans">
      <type>transmission_interface/SimpleTransmission</type>
      <joint name="link3_revolute">
      <hardwareInterface>hardware_interface/PositionJointInterface</hardwareInterface>
      </joint>
      <actuator name="link3_motor">
      <hardwareInterface>hardware_interface/PositionJointInterface</hardwareInterface>
      <mechanicalReduction>1</mechanicalReduction>
      </actuator>
  </transmission>

  <transmission name="link4_trans">
      <type>transmission_interface/SimpleTransmission</type>
      <joint name="link4_revolute">
      <hardwareInterface>hardware_interface/PositionJointInterface</hardwareInterface>
      </joint>
      <actuator name="link4_motor">
      <hardwareInterface>hardware_interface/PositionJointInterface</hardwareInterface>
      <mechanicalReduction>1</mechanicalReduction>
      </actuator>
  </transmission>

  <transmission name="link5_trans">
      <type>transmission_interface/SimpleTransmission</type>
      <joint name="link5_revolute">
      <hardwareInterface>hardware_interface/PositionJointInterface</hardwareInterface>
      </joint>
      <actuator name="link5_motor">
      <hardwareInterface>hardware_interface/PositionJointInterface</hardwareInterface>
      <mechanicalReduction>1</mechanicalReduction>
      </actuator>
  </transmission>

  <transmission name="link6_1_trans">
      <type>transmission_interface/SimpleTransmission</type>
      <joint name="link6_1_prismatic">
      <hardwareInterface>hardware_interface/PositionJointInterface</hardwareInterface>
      </joint>
      <actuator name="link6_1_motor">
      <hardwareInterface>hardware_interface/PositionJointInterface</hardwareInterface>
      <mechanicalReduction>1</mechanicalReduction>
      </actuator>
  </transmission>

    <transmission name="link6_2_trans">
      <type>transmission_interface/SimpleTransmission</type>
      <joint name="link6_2_prismatic">
      <hardwareInterface>hardware_interface/PositionJointInterface</hardwareInterface>
      </joint>
      <actuator name="link6_2_motor">
      <hardwareInterface>hardware_interface/PositionJointInterface</hardwareInterface>
      <mechanicalReduction>1</mechanicalReduction>
      </actuator>
  </transmission>

  <gazebo>
      <plugin name="control" filename="libgazebo_ros_control.so">
              <robotNamespace>/robotic_arm</robotNamespace>
      </plugin>
  </gazebo>

  <gazebo reference="link1">
        <selfCollide>true</selfCollide>
  </gazebo>

  <gazebo reference="link2">
        <selfCollide>true</selfCollide>
  </gazebo> 

  <gazebo reference="link3">
        <selfCollide>true</selfCollide>
  </gazebo>

  <gazebo reference="link4">
        <selfCollide>true</selfCollide>
  </gazebo>

  <gazebo reference="link5">
        <selfCollide>true</selfCollide>
  </gazebo>

  <gazebo reference="link6_1">
        <selfCollide>true</selfCollide>
  </gazebo>

  <gazebo reference="link6_2">
        <selfCollide>true</selfCollide>
  </gazebo>
</robot>
