<?xml version="1.0" encoding="utf-8"?>
<!-- This URDF was automatically created by SolidWorks to URDF Exporter! Originally created by Stephen Brawner (brawner@gmail.com) 
     Commit Version: 1.6.0-4-g7f85cfe  Build Version: 1.6.7995.38578
     For more information, please see http://wiki.ros.org/sw_urdf_exporter -->
<robot
  name="robotic_arm">
  <link
    name="base_link">
    <inertial>
      <origin
        xyz="0 0 0.07387601712051"
        rpy="0 0 0" />
      <mass
        value="17.1466031047213" />
      <inertia
        ixx="0.192001560775053"
        ixy="-4.94231267700497E-10"
        ixz="-5.42791823725335E-17"
        iyy="0.192001545021742"
        iyz="1.80071050509621E-17"
        izz="0.295440370143331" />
    </inertial>
    <visual>
      <origin
        xyz="0 0 0"
        rpy="0 0 0" />
      <geometry>
        <mesh
          filename="package://robotic_arm/meshes/base_link.STL" />
      </geometry>
      <material
        name="">
        <color
          rgba="0.792156862745098 0.819607843137255 0.933333333333333 1" />
      </material>
    </visual>
    <collision>
      <origin
        xyz="0 0 0"
        rpy="0 0 0" />
      <geometry>
        <mesh
          filename="package://robotic_arm/meshes/base_link.STL" />
      </geometry>
    </collision>
  </link>
  <link
    name="link1">
    <inertial>
      <origin
        xyz="-6.95221658020273E-13 -0.0945338927666912 -7.89606158235756E-11"
        rpy="0 0 0" />
      <mass
        value="3.09046329461166" />
      <inertia
        ixx="0.0263017337705573"
        ixy="-2.50228495151727E-15"
        ixz="-1.41634013545167E-12"
        iyy="0.0196320103484555"
        iyz="-7.45352139445325E-12"
        izz="0.0253879104888282" />
    </inertial>
    <visual>
      <origin
        xyz="0 0 0"
        rpy="0 0 0" />
      <geometry>
        <mesh
          filename="package://robotic_arm/meshes/link1.STL" />
      </geometry>
      <material
        name="">
        <color
          rgba="1 1 1 1" />
      </material>
    </visual>
    <collision>
      <origin
        xyz="0 0 0"
        rpy="0 0 0" />
      <geometry>
        <mesh
          filename="package://robotic_arm/meshes/link1.STL" />
      </geometry>
    </collision>
  </link>
  <joint
    name="link1_revolute"
    type="revolute">
    <origin
      xyz="0 0 0.405"
      rpy="1.5707963267949 0 -2.76394490191366" />
    <parent
      link="base_link" />
    <child
      link="link1" />
    <axis
      xyz="0 1 0" />
    <limit
      lower="0"
      upper="3.142"
      effort="0"
      velocity="0" />
  </joint>
  <link
    name="link2">
    <inertial>
      <origin
        xyz="-1.11022302462516E-16 0.167517809032193 0"
        rpy="0 0 0" />
      <mass
        value="5.58667658903741" />
      <inertia
        ixx="0.126324148269649"
        ixy="-1.01290721766884E-17"
        ixz="-3.46944695195361E-18"
        iyy="0.0114008236557686"
        iyz="3.77904971181924E-17"
        izz="0.1291146960145" />
    </inertial>
    <visual>
      <origin
        xyz="0 0 0"
        rpy="0 0 0" />
      <geometry>
        <mesh
          filename="package://robotic_arm/meshes/link2.STL" />
      </geometry>
      <material
        name="">
        <color
          rgba="0.792156862745098 0.819607843137255 0.933333333333333 1" />
      </material>
    </visual>
    <collision>
      <origin
        xyz="0 0 0"
        rpy="0 0 0" />
      <geometry>
        <mesh
          filename="package://robotic_arm/meshes/link2.STL" />
      </geometry>
    </collision>
  </link>
  <joint
    name="link2_revolute"
    type="revolute">
    <origin
      xyz="0 0 0"
      rpy="0 0 0" />
    <parent
      link="link1" />
    <child
      link="link2" />
    <axis
      xyz="0 0 1" />
    <limit
      lower="-1.57"
      upper="1.57"
      effort="0"
      velocity="0" />
  </joint>
  <link
    name="link3">
    <inertial>
      <origin
        xyz="-0.178930262065784 -1.22357679543939E-11 4.05058209196341E-11"
        rpy="0 0 0" />
      <mass
        value="2.82619520385501" />
      <inertia
        ixx="0.00740408211125268"
        ixy="-4.04702765982416E-12"
        ixz="-7.27377988569977E-12"
        iyy="0.0285515471747178"
        iyz="-3.4724193737957E-10"
        izz="0.025128092246159" />
    </inertial>
    <visual>
      <origin
        xyz="0 0 0"
        rpy="0 0 0" />
      <geometry>
        <mesh
          filename="package://robotic_arm/meshes/link3.STL" />
      </geometry>
      <material
        name="">
        <color
          rgba="0.792156862745098 0.819607843137255 0.933333333333333 1" />
      </material>
    </visual>
    <collision>
      <origin
        xyz="0 0 0"
        rpy="0 0 0" />
      <geometry>
        <mesh
          filename="package://robotic_arm/meshes/link3.STL" />
      </geometry>
    </collision>
  </link>
  <joint
    name="link3_revolute"
    type="revolute">
    <origin
      xyz="0 0.4 0"
      rpy="0 0 -0.016964" />
    <parent
      link="link2" />
    <child
      link="link3" />
    <axis
      xyz="0 0 1" />
    <limit
      lower="0"
      upper="3.142"
      effort="0"
      velocity="0" />
  </joint>
  <link
    name="link4">
    <inertial>
      <origin
        xyz="-0.401672173434541 0.400000000000003 5.32907051820075E-15"
        rpy="0 0 0" />
      <mass
        value="1.80974470730009" />
      <inertia
        ixx="0.00231117416637535"
        ixy="5.53383565100179E-17"
        ixz="6.77643298462385E-17"
        iyy="0.00961023623935307"
        iyz="3.03576608295941E-18"
        izz="0.00939078362141456" />
    </inertial>
    <visual>
      <origin
        xyz="0 0 0"
        rpy="0 0 0" />
      <geometry>
        <mesh
          filename="package://robotic_arm/meshes/link4.STL" />
      </geometry>
      <material
        name="">
        <color
          rgba="0.792156862745098 0.819607843137255 0.933333333333333 1" />
      </material>
    </visual>
    <collision>
      <origin
        xyz="0 0 0"
        rpy="0 0 0" />
      <geometry>
        <mesh
          filename="package://robotic_arm/meshes/link4.STL" />
      </geometry>
    </collision>
  </link>
  <joint
    name="link4_revolute"
    type="revolute">
    <origin
      xyz="0.0500000000000015 0.35 0"
      rpy="0 0 1.5707963267949" />
    <parent
      link="link3" />
    <child
      link="link4" />
    <axis
      xyz="0 0 1" />
    <limit
      lower="0"
      upper="-3.142"
      effort="0"
      velocity="0" />
  </joint>
  <link
    name="link5">
    <inertial>
      <origin
        xyz="-0.558543881270101 0.39999999997842 -5.83033621381901E-11"
        rpy="0 0 0" />
      <mass
        value="0.190534240004917" />
      <inertia
        ixx="0.000301965070175209"
        ixy="-3.14177825436035E-14"
        ixz="-5.5472344575598E-14"
        iyy="0.000228167325953282"
        iyz="-1.96410005094813E-11"
        izz="0.000118429273236204" />
    </inertial>
    <visual>
      <origin
        xyz="0 0 0"
        rpy="0 0 0" />
      <geometry>
        <mesh
          filename="package://robotic_arm/meshes/link5.STL" />
      </geometry>
      <material
        name="">
        <color
          rgba="0.792156862745098 0.819607843137255 0.933333333333333 1" />
      </material>
    </visual>
    <collision>
      <origin
        xyz="0 0 0"
        rpy="0 0 0" />
      <geometry>
        <mesh
          filename="package://robotic_arm/meshes/link5.STL" />
      </geometry>
    </collision>
  </link>
  <joint
    name="link5_revolute"
    type="revolute">
    <origin
      xyz="0.002 0.8 0"
      rpy="3.1416 0 0" />
    <parent
      link="link4" />
    <child
      link="link5" />
    <axis
      xyz="1 0 0" />
    <limit
      lower="0"
      upper="3.142"
      effort="0"
      velocity="0" />
  </joint>
  <link
    name="link6_1">
    <inertial>
      <origin
        xyz="-0.602368573581712 0.399999999999995 -0.0160129768886617"
        rpy="0 0 0" />
      <mass
        value="0.116532917792388" />
      <inertia
        ixx="3.92458903876163E-05"
        ixy="-3.71609235828223E-19"
        ixz="1.02579257431564E-05"
        iyy="7.11886398907226E-05"
        iyz="1.55854062294791E-19"
        izz="8.48753968585235E-05" />
    </inertial>
    <visual>
      <origin
        xyz="0 0 0"
        rpy="0 0 0" />
      <geometry>
        <mesh
          filename="package://robotic_arm/meshes/link6_1.STL" />
      </geometry>
      <material
        name="">
        <color
          rgba="0.792156862745098 0.819607843137255 0.933333333333333 1" />
      </material>
    </visual>
    <collision>
      <origin
        xyz="0 0 0"
        rpy="0 0 0" />
      <geometry>
        <mesh
          filename="package://robotic_arm/meshes/link6_1.STL" />
      </geometry>
    </collision>
  </link>
  <joint
    name="link6_1_prismatic"
    type="prismatic">
    <origin
      xyz="0 0 -0.0100000010821744"
      rpy="0 0 0" />
    <parent
      link="link5" />
    <child
      link="link6_1" />
    <axis
      xyz="0 0 1" />
    <limit
      lower="0"
      upper="0.03"
      effort="0"
      velocity="0" />
  </joint>
  <link
    name="link6_2">
    <inertial>
      <origin
        xyz="-0.602368573581706 0.400000000000005 -0.016012976888649"
        rpy="0 0 0" />
      <mass
        value="0.116532917792388" />
      <inertia
        ixx="3.92458903876158E-05"
        ixy="3.4115575439647E-19"
        ixz="1.02579257431571E-05"
        iyy="7.11886398907144E-05"
        iyz="-2.23616698075135E-19"
        izz="8.48753968585148E-05" />
    </inertial>
    <visual>
      <origin
        xyz="0 0 0"
        rpy="0 0 0" />
      <geometry>
        <mesh
          filename="package://robotic_arm/meshes/link6_2.STL" />
      </geometry>
      <material
        name="">
        <color
          rgba="0.792156862745098 0.819607843137255 0.933333333333333 1" />
      </material>
    </visual>
    <collision>
      <origin
        xyz="0 0 0"
        rpy="0 0 0" />
      <geometry>
        <mesh
          filename="package://robotic_arm/meshes/link6_2.STL" />
      </geometry>
    </collision>
  </link>
  <joint
    name="link6_1_prismatic"
    type="prismatic">
    <origin
      xyz="0 0.8 0.0100000010811965"
      rpy="3.14159265358979 0 0" />
    <parent
      link="link5" />
    <child
      link="link6_2" />
    <axis
      xyz="0 0 -1" />
    <limit
      lower="-0.03"
      upper="0"
      effort="0"
      velocity="0" />
  </joint>
</robot>