<?xml version="1.0" encoding="utf-8"?>
<!-- This URDF was automatically created by SolidWorks to URDF Exporter! Originally created by Stephen Brawner (brawner@gmail.com) 
     Commit Version: 1.6.0-4-g7f85cfe  Build Version: 1.6.7995.38578
     For more information, please see http://wiki.ros.org/sw_urdf_exporter -->
<robot
  name="robotic arm">
  <link
    name="base_link">
    <inertial>
      <origin
        xyz="0 0 0.073876"
        rpy="0 0 0" />
      <mass
        value="17.147" />
      <inertia
        ixx="0.192"
        ixy="-4.9423E-10"
        ixz="-5.3264E-17"
        iyy="0.192"
        iyz="1.8692E-17"
        izz="0.29544" />
    </inertial>
    <visual>
      <origin
        xyz="0 0 0"
        rpy="0 0 0" />
      <geometry>
        <mesh
          filename="package://robotic arm/meshes/base_link.STL" />
      </geometry>
      <material
        name="">
        <color
          rgba="0.79216 0.81961 0.93333 1" />
      </material>
    </visual>
    <collision>
      <origin
        xyz="0 0 0"
        rpy="0 0 0" />
      <geometry>
        <mesh
          filename="package://robotic arm/meshes/base_link.STL" />
      </geometry>
    </collision>
  </link>
  <link
    name="link1">
    <inertial>
      <origin
        xyz="-6.95221658020273E-13 -0.0945338927666912 -7.89606158235756E-11"
        rpy="0 0 0" />
      <mass
        value="3.09046329461166" />
      <inertia
        ixx="0.0263017337705573"
        ixy="-2.50414863135214E-15"
        ixz="-1.41634187017514E-12"
        iyy="0.0196320103484555"
        iyz="-7.45352126692742E-12"
        izz="0.0253879104888282" />
    </inertial>
    <visual>
      <origin
        xyz="0 0 0"
        rpy="0 0 0" />
      <geometry>
        <mesh
          filename="package://robotic arm/meshes/link1.STL" />
      </geometry>
      <material
        name="">
        <color
          rgba="1 1 1 1" />
      </material>
    </visual>
    <collision>
      <origin
        xyz="0 0 0"
        rpy="0 0 0" />
      <geometry>
        <mesh
          filename="package://robotic arm/meshes/link1.STL" />
      </geometry>
    </collision>
  </link>
  <joint
    name="link1_revolute"
    type="revolute">
    <origin
      xyz="0 0 0.405"
      rpy="1.5708 0 -2.7639" />
    <parent
      link="base_link" />
    <child
      link="link1" />
    <axis
      xyz="0 0 0" />
    <limit
      lower="0"
      upper="3.142"
      effort="0"
      velocity="0" />
  </joint>
  <link
    name="link2">
    <inertial>
      <origin
        xyz="-1.11022302462516E-16 0.167517809032193 0"
        rpy="0 0 0" />
      <mass
        value="5.58667658903741" />
      <inertia
        ixx="0.126324148269649"
        ixy="-1.14239522335993E-17"
        ixz="-1.38777878078145E-17"
        iyy="0.0114008236557685"
        iyz="3.76221794962853E-17"
        izz="0.1291146960145" />
    </inertial>
    <visual>
      <origin
        xyz="0 0 0"
        rpy="0 0 0" />
      <geometry>
        <mesh
          filename="package://robotic arm/meshes/link2.STL" />
      </geometry>
      <material
        name="">
        <color
          rgba="0.792156862745098 0.819607843137255 0.933333333333333 1" />
      </material>
    </visual>
    <collision>
      <origin
        xyz="0 0 0"
        rpy="0 0 0" />
      <geometry>
        <mesh
          filename="package://robotic arm/meshes/link2.STL" />
      </geometry>
    </collision>
  </link>
  <joint
    name="link2_revolute"
    type="revolute">
    <origin
      xyz="0 0 0"
      rpy="0 0 0" />
    <parent
      link="link1" />
    <child
      link="link2" />
    <axis
      xyz="0 0 0" />
    <limit
      lower="-1.57"
      upper="1.57"
      effort="0"
      velocity="0" />
  </joint>
  <link
    name="link3">
    <inertial>
      <origin
        xyz="-0.178930262065784 -1.22357679543939E-11 4.05058209196341E-11"
        rpy="0 0 0" />
      <mass
        value="2.82619520385501" />
      <inertia
        ixx="0.00740408211125266"
        ixy="-4.04702923022325E-12"
        ixz="-7.2737857403915E-12"
        iyy="0.0285515471747178"
        iyz="-3.47241934628407E-10"
        izz="0.025128092246159" />
    </inertial>
    <visual>
      <origin
        xyz="0 0 0"
        rpy="0 0 0" />
      <geometry>
        <mesh
          filename="package://robotic arm/meshes/link3.STL" />
      </geometry>
      <material
        name="">
        <color
          rgba="0.792156862745098 0.819607843137255 0.933333333333333 1" />
      </material>
    </visual>
    <collision>
      <origin
        xyz="0 0 0"
        rpy="0 0 0" />
      <geometry>
        <mesh
          filename="package://robotic arm/meshes/link3.STL" />
      </geometry>
    </collision>
  </link>
  <joint
    name="link3_revolute"
    type="revolute">
    <origin
      xyz="0 0.4 0"
      rpy="0 0 -0.016964" />
    <parent
      link="link2" />
    <child
      link="link3" />
    <axis
      xyz="0 0 1" />
    <limit
      lower="0"
      upper="3.142"
      effort="0"
      velocity="0" />
  </joint>
  <link
    name="link4">
    <inertial>
      <origin
        xyz="-0.401672173434541 0.400000000000003 5.32907051820075E-15"
        rpy="0 0 0" />
      <mass
        value="1.80974470730009" />
      <inertia
        ixx="0.00231117416637535"
        ixy="5.5008860693536E-17"
        ixz="6.59635378003759E-17"
        iyy="0.00961023623935307"
        iyz="3.68628738645072E-18"
        izz="0.00939078362141456" />
    </inertial>
    <visual>
      <origin
        xyz="0 0 0"
        rpy="0 0 0" />
      <geometry>
        <mesh
          filename="package://robotic arm/meshes/link4.STL" />
      </geometry>
      <material
        name="">
        <color
          rgba="0.792156862745098 0.819607843137255 0.933333333333333 1" />
      </material>
    </visual>
    <collision>
      <origin
        xyz="0 0 0"
        rpy="0 0 0" />
      <geometry>
        <mesh
          filename="package://robotic arm/meshes/link4.STL" />
      </geometry>
    </collision>
  </link>
  <joint
    name="link4_revolute"
    type="revolute">
    <origin
      xyz="0.05 0.35 0"
      rpy="0 0 1.5708" />
    <parent
      link="link3" />
    <child
      link="link4" />
    <axis
      xyz="0 0 0" />
    <limit
      lower="0"
      upper="-3.142"
      effort="0"
      velocity="0" />
  </joint>
  <link
    name="link5">
    <inertial>
      <origin
        xyz="-0.558543881270102 0.39999999997842 -5.83031400935852E-11"
        rpy="0 0 0" />
      <mass
        value="0.190534240004917" />
      <inertia
        ixx="0.000301965070175209"
        ixy="-3.14177765614333E-14"
        ixz="-5.54723439403233E-14"
        iyy="0.000228167325953282"
        iyz="-1.96410006754997E-11"
        izz="0.000118429273236205" />
    </inertial>
    <visual>
      <origin
        xyz="0 0 0"
        rpy="0 0 0" />
      <geometry>
        <mesh
          filename="package://robotic arm/meshes/link5.STL" />
      </geometry>
      <material
        name="">
        <color
          rgba="0.792156862745098 0.819607843137255 0.933333333333333 1" />
      </material>
    </visual>
    <collision>
      <origin
        xyz="0 0 0"
        rpy="0 0 0" />
      <geometry>
        <mesh
          filename="package://robotic arm/meshes/link5.STL" />
      </geometry>
    </collision>
  </link>
  <joint
    name="link5_revolute"
    type="revolute">
    <origin
      xyz="0.002 0.8 0"
      rpy="3.1416 0 0" />
    <parent
      link="link4" />
    <child
      link="link5" />
    <axis
      xyz="0 0 0" />
    <limit
      lower="0"
      upper="3.142"
      effort="0"
      velocity="0" />
  </joint>
  <link
    name="link6_1">
    <inertial>
      <origin
        xyz="-0.602368573581712 0.399999999999995 -0.0160129768886617"
        rpy="0 0 0" />
      <mass
        value="0.116532917792388" />
      <inertia
        ixx="3.92458903876167E-05"
        ixy="-2.98962925711365E-19"
        ixz="1.02579257431564E-05"
        iyy="7.11886398907158E-05"
        iyz="1.74488787134386E-19"
        izz="8.48753968585171E-05" />
    </inertial>
    <visual>
      <origin
        xyz="0 0 0"
        rpy="0 0 0" />
      <geometry>
        <mesh
          filename="package://robotic arm/meshes/link6_1.STL" />
      </geometry>
      <material
        name="">
        <color
          rgba="0.792156862745098 0.819607843137255 0.933333333333333 1" />
      </material>
    </visual>
    <collision>
      <origin
        xyz="0 0 0"
        rpy="0 0 0" />
      <geometry>
        <mesh
          filename="package://robotic arm/meshes/link6_1.STL" />
      </geometry>
    </collision>
  </link>
  <joint
    name="link6_1_prismatic"
    type="prismatic">
    <origin
      xyz="0 0 -0.01"
      rpy="0 0 0" />
    <parent
      link="link5" />
    <child
      link="link6_1" />
    <axis
      xyz="0 0 0" />
    <limit
      lower="0"
      upper="0.03"
      effort="0"
      velocity="0" />
  </joint>
  <link
    name="link6_2">
    <inertial>
      <origin
        xyz="-0.602368573581706 0.400000000000005 -0.016012976888649"
        rpy="0 0 0" />
      <mass
        value="0.116532917792388" />
      <inertia
        ixx="3.92458903876163E-05"
        ixy="1.77281348882365E-19"
        ixz="1.0257925743157E-05"
        iyy="7.11886398907144E-05"
        iyz="-2.87991202066462E-19"
        izz="8.48753968585153E-05" />
    </inertial>
    <visual>
      <origin
        xyz="0 0 0"
        rpy="0 0 0" />
      <geometry>
        <mesh
          filename="package://robotic arm/meshes/link6_2.STL" />
      </geometry>
      <material
        name="">
        <color
          rgba="0.792156862745098 0.819607843137255 0.933333333333333 1" />
      </material>
    </visual>
    <collision>
      <origin
        xyz="0 0 0"
        rpy="0 0 0" />
      <geometry>
        <mesh
          filename="package://robotic arm/meshes/link6_2.STL" />
      </geometry>
    </collision>
  </link>
  <joint
    name="link6_1_prismatic"
    type="prismatic">
    <origin
      xyz="0 0.8 0.01"
      rpy="3.1416 0 0" />
    <parent
      link="link5" />
    <child
      link="link6_2" />
    <axis
      xyz="0 0 0" />
    <limit
      lower="-0.03"
      upper="0"
      effort="0"
      velocity="0" />
  </joint>
</robot>