<?xml version="1.0" encoding="utf-8"?>
<!-- This URDF was automatically created by SolidWorks to URDF Exporter! Originally created by Stephen Brawner (brawner@gmail.com) 
     Commit Version: 1.6.0-4-g7f85cfe  Build Version: 1.6.7995.38578
     For more information, please see http://wiki.ros.org/sw_urdf_exporter -->
<robot
  name="tractor">
  <link
    name="base_link">
    <inertial>
      <origin
        xyz="0.17138 0.086311 0.0015789"
        rpy="0 0 0" />
      <mass
        value="3290" />
      <inertia
        ixx="1159.4"
        ixy="0.29134"
        ixz="-4.5216"
        iyy="2316.6"
        iyz="-0.62634"
        izz="1715.6" />
    </inertial>
    <visual>
      <origin
        xyz="0 0 0"
        rpy="0 0 0" />
      <geometry>
        <mesh
          filename="package://tractor/meshes/base_link.STL" />
      </geometry>
      <material
        name="">
        <color
          rgba="1 0.94902 0.9098 1" />
      </material>
    </visual>
    <collision>
      <origin
        xyz="0 0 0"
        rpy="0 0 0" />
      <geometry>
        <mesh
          filename="package://tractor/meshes/base_link.STL" />
      </geometry>
    </collision>
  </link>
  <link
    name="FRONT_L">
    <inertial>
      <origin
        xyz="0.171382568969737 0.086311077026464 0.00157888042384252"
        rpy="0 0 0" />
      <mass
        value="3290" />
      <inertia
        ixx="1159.37197911485"
        ixy="0.29133848407538"
        ixz="-4.52157880474249"
        iyy="2316.59852393119"
        iyz="-0.62634403797237"
        izz="1715.57929201288" />
    </inertial>
    <visual>
      <origin
        xyz="0 0 0"
        rpy="0 0 0" />
      <geometry>
        <mesh
          filename="package://tractor/meshes/FRONT_L.STL" />
      </geometry>
      <material
        name="">
        <color
          rgba="0.792156862745098 0.819607843137255 0.933333333333333 1" />
      </material>
    </visual>
    <collision>
      <origin
        xyz="0 0 0"
        rpy="0 0 0" />
      <geometry>
        <mesh
          filename="package://tractor/meshes/FRONT_L.STL" />
      </geometry>
    </collision>
  </link>
  <joint
    name="Front1"
    type="continuous">
    <origin
      xyz="0.70935 0.51409 -0.13999"
      rpy="-1.5708 0 0" />
    <parent
      link="base_link" />
    <child
      link="FRONT_L" />
    <axis
      xyz="0 0 -1" />
    <limit
      lower="-0.8203"
      upper="0.8203"
      effort="0"
      velocity="0" />
  </joint>
  <link
    name="Front_LR">
    <inertial>
      <origin
        xyz="0.171382568969737 0.086311077026464 0.00157888042384252"
        rpy="0 0 0" />
      <mass
        value="3290" />
      <inertia
        ixx="1159.37197911485"
        ixy="0.29133848407538"
        ixz="-4.52157880474249"
        iyy="2316.59852393119"
        iyz="-0.62634403797237"
        izz="1715.57929201288" />
    </inertial>
    <visual>
      <origin
        xyz="0 0 0"
        rpy="0 0 0" />
      <geometry>
        <mesh
          filename="package://tractor/meshes/Front_LR.STL" />
      </geometry>
      <material
        name="">
        <color
          rgba="0.792156862745098 0.819607843137255 0.933333333333333 1" />
      </material>
    </visual>
    <collision>
      <origin
        xyz="0 0 0"
        rpy="0 0 0" />
      <geometry>
        <mesh
          filename="package://tractor/meshes/Front_LR.STL" />
      </geometry>
    </collision>
  </link>
  <joint
    name="Front1R"
    type="revolute">
    <origin
      xyz="0.70935 0.51409 -0.13999"
      rpy="0 0 0" />
    <parent
      link="base_link" />
    <child
      link="Front_LR" />
    <axis
      xyz="0 0 1" />
    <limit
      lower="0.5585"
      upper="0.8203"
      effort="0"
      velocity="0" />
  </joint>
  <link
    name="FRONT_R">
    <inertial>
      <origin
        xyz="0.171382568969737 0.086311077026464 0.00157888042384252"
        rpy="0 0 0" />
      <mass
        value="3290" />
      <inertia
        ixx="1159.37197911485"
        ixy="0.29133848407538"
        ixz="-4.52157880474249"
        iyy="2316.59852393119"
        iyz="-0.62634403797237"
        izz="1715.57929201288" />
    </inertial>
    <visual>
      <origin
        xyz="0 0 0"
        rpy="0 0 0" />
      <geometry>
        <mesh
          filename="package://tractor/meshes/FRONT_R.STL" />
      </geometry>
      <material
        name="">
        <color
          rgba="0.792156862745098 0.819607843137255 0.933333333333333 1" />
      </material>
    </visual>
    <collision>
      <origin
        xyz="0 0 0"
        rpy="0 0 0" />
      <geometry>
        <mesh
          filename="package://tractor/meshes/FRONT_R.STL" />
      </geometry>
    </collision>
  </link>
  <joint
    name="Front2"
    type="continuous">
    <origin
      xyz="0.70935 -0.51409 -0.13999"
      rpy="-1.5708 0 0" />
    <parent
      link="base_link" />
    <child
      link="FRONT_R" />
    <axis
      xyz="0 0 1" />
    <limit
      effort="0"
      velocity="0" />
  </joint>
  <link
    name="FRONT_RR">
    <inertial>
      <origin
        xyz="0.171382568969737 0.086311077026464 0.00157888042384252"
        rpy="0 0 0" />
      <mass
        value="3290" />
      <inertia
        ixx="1159.37197911485"
        ixy="0.29133848407538"
        ixz="-4.52157880474249"
        iyy="2316.59852393119"
        iyz="-0.62634403797237"
        izz="1715.57929201288" />
    </inertial>
    <visual>
      <origin
        xyz="0 0 0"
        rpy="0 0 0" />
      <geometry>
        <mesh
          filename="package://tractor/meshes/FRONT_RR.STL" />
      </geometry>
      <material
        name="">
        <color
          rgba="1 1 1 1" />
      </material>
    </visual>
    <collision>
      <origin
        xyz="0 0 0"
        rpy="0 0 0" />
      <geometry>
        <mesh
          filename="package://tractor/meshes/FRONT_RR.STL" />
      </geometry>
    </collision>
  </link>
  <joint
    name="Front2R"
    type="revolute">
    <origin
      xyz="0.70935 -0.51409 -0.13999"
      rpy="0 0 0" />
    <parent
      link="base_link" />
    <child
      link="FRONT_RR" />
    <axis
      xyz="0 0 1" />
    <limit
      lower="0.5585"
      upper="0.8203"
      effort="0"
      velocity="0" />
    <mimic
      joint="Front1R"
      multiplier="0.68"
      offset="0" />
  </joint>
  <link
    name="REAR_L">
    <inertial>
      <origin
        xyz="0.171382568969737 0.086311077026464 0.00157888042384252"
        rpy="0 0 0" />
      <mass
        value="3290" />
      <inertia
        ixx="1159.37197911485"
        ixy="0.29133848407538"
        ixz="-4.52157880474249"
        iyy="2316.59852393119"
        iyz="-0.62634403797237"
        izz="1715.57929201288" />
    </inertial>
    <visual>
      <origin
        xyz="0 0 0"
        rpy="0 0 0" />
      <geometry>
        <mesh
          filename="package://tractor/meshes/REAR_L.STL" />
      </geometry>
      <material
        name="">
        <color
          rgba="0.792156862745098 0.819607843137255 0.933333333333333 1" />
      </material>
    </visual>
    <collision>
      <origin
        xyz="0 0 0"
        rpy="0 0 0" />
      <geometry>
        <mesh
          filename="package://tractor/meshes/REAR_L.STL" />
      </geometry>
    </collision>
  </link>
  <joint
    name="Rear1"
    type="continuous">
    <origin
      xyz="-0.65 0.77 0.055"
      rpy="-1.5708 0 0" />
    <parent
      link="base_link" />
    <child
      link="REAR_L" />
    <axis
      xyz="0 0 -1" />
    <limit
      effort="0"
      velocity="0" />
  </joint>
  <link
    name="REAR_R">
    <inertial>
      <origin
        xyz="0.171382568969737 0.086311077026464 0.00157888042384252"
        rpy="0 0 0" />
      <mass
        value="3290" />
      <inertia
        ixx="1159.37197911485"
        ixy="0.29133848407538"
        ixz="-4.52157880474249"
        iyy="2316.59852393119"
        iyz="-0.62634403797237"
        izz="1715.57929201288" />
    </inertial>
    <visual>
      <origin
        xyz="0 0 0"
        rpy="0 0 0" />
      <geometry>
        <mesh
          filename="package://tractor/meshes/REAR_R.STL" />
      </geometry>
      <material
        name="">
        <color
          rgba="0.792156862745098 0.819607843137255 0.933333333333333 1" />
      </material>
    </visual>
    <collision>
      <origin
        xyz="0 0 0"
        rpy="0 0 0" />
      <geometry>
        <mesh
          filename="package://tractor/meshes/REAR_R.STL" />
      </geometry>
    </collision>
  </link>
  <joint
    name="Rear2"
    type="continuous">
    <origin
      xyz="-0.65 -0.77 0.055"
      rpy="-1.5708 0 0" />
    <parent
      link="base_link" />
    <child
      link="REAR_R" />
    <axis
      xyz="0 0 1" />
    <limit
      effort="0"
      velocity="0" />
  </joint>
</robot>