<?xml version="1.0" encoding="utf-8"?>
<!-- This URDF was automatically created by SolidWorks to URDF Exporter! Originally created by Stephen Brawner (brawner@gmail.com) 
     Commit Version: 1.6.0-4-g7f85cfe  Build Version: 1.6.7995.38578
     For more information, please see http://wiki.ros.org/sw_urdf_exporter -->
<robot
  name="tractor">
  <link
    name="base_link">
    <inertial>
      <origin
        xyz="0.17142 0.086225 0.0015789"
        rpy="0 0 0" />
      <mass
        value="2890" />
      <inertia
        ixx="1197.4"
        ixy="75.897"
        ixz="-0.9722"
        iyy="5296.7"
        iyz="-1.196"
        izz="4747.4" />
    </inertial>
    <visual>
      <origin
        xyz="0 0 0"
        rpy="0 0 0" />
      <geometry>
        <mesh
          filename="package://tractor/meshes/base_link.STL" />
      </geometry>
      <material
        name="">
        <color
          rgba="1 0.94902 0.9098 1" />
      </material>
    </visual>
    <collision>
      <origin
        xyz="0 0 0"
        rpy="0 0 0" />
      <geometry>
        <mesh
          filename="package://tractor/meshes/base_link.STL" />
      </geometry>
    </collision>
  </link>
  <link
    name="Front_L">
    <inertial>
      <origin
        xyz="0.17142 0.086225 0.0015789"
        rpy="0 0 0" />
      <mass
        value="100" />
      <inertia
        ixx="1197.4"
        ixy="75.897"
        ixz="-0.9722"
        iyy="5296.7"
        iyz="-1.196"
        izz="4747.4" />
    </inertial>
    <visual>
      <origin
        xyz="0 0 0"
        rpy="0 0 0" />
      <geometry>
        <mesh
          filename="package://tractor/meshes/Front_L.STL" />
      </geometry>
      <material
        name="">
        <color
          rgba="0.79216 0.81961 0.93333 1" />
      </material>
    </visual>
    <collision>
      <origin
        xyz="0 0 0"
        rpy="0 0 0" />
      <geometry>
        <mesh
          filename="package://tractor/meshes/Front_L.STL" />
      </geometry>
    </collision>
  </link>
  <joint
    name="Front1"
    type="continuous">
    <origin
      xyz="1.6143 -0.81922 -0.13999"
      rpy="0 0 0" />
    <parent
      link="base_link" />
    <child
      link="Front_L" />
    <axis
      xyz="0 1 0" />
  </joint>
  <link
    name="Front_R">
    <inertial>
      <origin
        xyz="0.17142 0.086225 0.0015789"
        rpy="0 0 0" />
      <mass
        value="100" />
      <inertia
        ixx="1197.4"
        ixy="75.897"
        ixz="-0.9722"
        iyy="5296.7"
        iyz="-1.196"
        izz="4747.4" />
    </inertial>
    <visual>
      <origin
        xyz="0 0 0"
        rpy="0 0 0" />
      <geometry>
        <mesh
          filename="package://tractor/meshes/Front_R.STL" />
      </geometry>
      <material
        name="">
        <color
          rgba="0.79216 0.81961 0.93333 1" />
      </material>
    </visual>
    <collision>
      <origin
        xyz="0 0 0"
        rpy="0 0 0" />
      <geometry>
        <mesh
          filename="package://tractor/meshes/Front_R.STL" />
      </geometry>
    </collision>
  </link>
  <joint
    name="Front2"
    type="continuous">
    <origin
      xyz="1.6143 0.81922 -0.13999"
      rpy="0 0 0" />
    <parent
      link="base_link" />
    <child
      link="Front_R" />
    <axis
      xyz="0 1 0" />
  </joint>
  <link
    name="Rear_L">
    <inertial>
      <origin
        xyz="0.17142 0.086225 0.0015789"
        rpy="0 0 0" />
      <mass
        value="100" />
      <inertia
        ixx="1197.4"
        ixy="75.897"
        ixz="-0.9722"
        iyy="5296.7"
        iyz="-1.196"
        izz="4747.4" />
    </inertial>
    <visual>
      <origin
        xyz="0 0 0"
        rpy="0 0 0" />
      <geometry>
        <mesh
          filename="package://tractor/meshes/Rear_L.STL" />
      </geometry>
      <material
        name="">
        <color
          rgba="0.79216 0.81961 0.93333 1" />
      </material>
    </visual>
    <collision>
      <origin
        xyz="0 0 0"
        rpy="0 0 0" />
      <geometry>
        <mesh
          filename="package://tractor/meshes/Rear_L.STL" />
      </geometry>
    </collision>
  </link>
  <joint
    name="Rear1"
    type="continuous">
    <origin
      xyz="-0.65 -0.77 0.055"
      rpy="0 0 0" />
    <parent
      link="base_link" />
    <child
      link="Rear_L" />
    <axis
      xyz="0 1 0" />
  </joint>
  <link
    name="Rear_R">
    <inertial>
      <origin
        xyz="0.17142 0.086225 0.0015789"
        rpy="0 0 0" />
      <mass
        value="100" />
      <inertia
        ixx="1197.4"
        ixy="75.897"
        ixz="-0.9722"
        iyy="5296.7"
        iyz="-1.196"
        izz="4747.4" />
    </inertial>
    <visual>
      <origin
        xyz="0 0 0"
        rpy="0 0 0" />
      <geometry>
        <mesh
          filename="package://tractor/meshes/Rear_R.STL" />
      </geometry>
      <material
        name="">
        <color
          rgba="0.79216 0.81961 0.93333 1" />
      </material>
    </visual>
    <collision>
      <origin
        xyz="0 0 0"
        rpy="0 0 0" />
      <geometry>
        <mesh
          filename="package://tractor/meshes/Rear_R.STL" />
      </geometry>
    </collision>
  </link>
  <joint
    name="Rear2"
    type="continuous">
    <origin
      xyz="-0.65 0.77 0.055"
      rpy="0 0 0" />
    <parent
      link="base_link" />
    <child
      link="Rear_R" />
    <axis
      xyz="0 1 0" />
  </joint>
  <link
    name="UL">
    <inertial>
      <origin
        xyz="0.17142 0.086225 0.0015789"
        rpy="0 0 0" />
      <mass
        value="30" />
      <inertia
        ixx="1197.4"
        ixy="75.897"
        ixz="-0.9722"
        iyy="5296.7"
        iyz="-1.196"
        izz="4747.4" />
    </inertial>
    <visual>
      <origin
        xyz="0 0 0"
        rpy="0 0 0" />
      <geometry>
        <mesh
          filename="package://tractor/meshes/UL.STL" />
      </geometry>
      <material
        name="">
        <color
          rgba="1 0.94902 0.9098 1" />
      </material>
    </visual>
    <collision>
      <origin
        xyz="0 0 0"
        rpy="0 0 0" />
      <geometry>
        <mesh
          filename="package://tractor/meshes/UL.STL" />
      </geometry>
    </collision>
  </link>
  <joint
    name="ul"
    type="revolute">
    <origin
      xyz="-0.72832 0.2 0.405"
      rpy="0 0 0" />
    <parent
      link="base_link" />
    <child
      link="UL" />
    <axis
      xyz="0 1 0" />
    <limit
      lower="0"
      upper="0"
      effort="0"
      velocity="0" />
  </joint>
  <link
    name="UR">
    <inertial>
      <origin
        xyz="0.17142 0.086225 0.0015789"
        rpy="0 0 0" />
      <mass
        value="30" />
      <inertia
        ixx="1197.4"
        ixy="75.897"
        ixz="-0.9722"
        iyy="5296.7"
        iyz="-1.196"
        izz="4747.4" />
    </inertial>
    <visual>
      <origin
        xyz="0 0 0"
        rpy="0 0 0" />
      <geometry>
        <mesh
          filename="package://tractor/meshes/UR.STL" />
      </geometry>
      <material
        name="">
        <color
          rgba="1 0.94902 0.9098 1" />
      </material>
    </visual>
    <collision>
      <origin
        xyz="0 0 0"
        rpy="0 0 0" />
      <geometry>
        <mesh
          filename="package://tractor/meshes/UR.STL" />
      </geometry>
    </collision>
  </link>
  <joint
    name="ur"
    type="continuous">
    <origin
      xyz="-0.72832 -0.2 0.405"
      rpy="0 0 0" />
    <parent
      link="base_link" />
    <child
      link="UR" />
    <axis
      xyz="0 1 0" />
  </joint>
  <link
    name="LL">
    <inertial>
      <origin
        xyz="0.17142 0.086225 0.0015789"
        rpy="0 0 0" />
      <mass
        value="10" />
      <inertia
        ixx="1197.4"
        ixy="75.897"
        ixz="-0.9722"
        iyy="5296.7"
        iyz="-1.196"
        izz="4747.4" />
    </inertial>
    <visual>
      <origin
        xyz="0 0 0"
        rpy="0 0 0" />
      <geometry>
        <mesh
          filename="package://tractor/meshes/LL.STL" />
      </geometry>
      <material
        name="">
        <color
          rgba="1 0.94902 0.9098 1" />
      </material>
    </visual>
    <collision>
      <origin
        xyz="0 0 0"
        rpy="0 0 0" />
      <geometry>
        <mesh
          filename="package://tractor/meshes/LL.STL" />
      </geometry>
    </collision>
  </link>
  <joint
    name="ll"
    type="revolute">
    <origin
      xyz="-0.72075 0.27 -0.076346"
      rpy="0 0 0" />
    <parent
      link="base_link" />
    <child
      link="LL" />
    <axis
      xyz="0 1 0" />
    <limit
      lower="0"
      upper="0"
      effort="0"
      velocity="0" />
  </joint>
  <link
    name="LR">
    <inertial>
      <origin
        xyz="0.17142 0.086225 0.0015789"
        rpy="0 0 0" />
      <mass
        value="10" />
      <inertia
        ixx="1197.4"
        ixy="75.897"
        ixz="-0.9722"
        iyy="5296.7"
        iyz="-1.196"
        izz="4747.4" />
    </inertial>
    <visual>
      <origin
        xyz="0 0 0"
        rpy="0 0 0" />
      <geometry>
        <mesh
          filename="package://tractor/meshes/LR.STL" />
      </geometry>
      <material
        name="">
        <color
          rgba="1 0.94902 0.9098 1" />
      </material>
    </visual>
    <collision>
      <origin
        xyz="0 0 0"
        rpy="0 0 0" />
      <geometry>
        <mesh
          filename="package://tractor/meshes/LR.STL" />
      </geometry>
    </collision>
  </link>
  <joint
    name="lr"
    type="revolute">
    <origin
      xyz="-0.72075 -0.27 -0.076346"
      rpy="0 0 0" />
    <parent
      link="base_link" />
    <child
      link="LR" />
    <axis
      xyz="0 1 0" />
    <limit
      lower="0"
      upper="0"
      effort="0"
      velocity="0" />
  </joint>
  <link
    name="TP1">
    <inertial>
      <origin
        xyz="0.17142 0.086225 0.0015789"
        rpy="0 0 0" />
      <mass
        value="6" />
      <inertia
        ixx="1197.4"
        ixy="75.897"
        ixz="-0.9722"
        iyy="5296.7"
        iyz="-1.196"
        izz="4747.4" />
    </inertial>
    <visual>
      <origin
        xyz="0 0 0"
        rpy="0 0 0" />
      <geometry>
        <mesh
          filename="package://tractor/meshes/TP1.STL" />
      </geometry>
      <material
        name="">
        <color
          rgba="1 1 1 1" />
      </material>
    </visual>
    <collision>
      <origin
        xyz="0 0 0"
        rpy="0 0 0" />
      <geometry>
        <mesh
          filename="package://tractor/meshes/TP1.STL" />
      </geometry>
    </collision>
  </link>
  <joint
    name="tp1"
    type="revolute">
    <origin
      xyz="-0.985 0.010158 0.245"
      rpy="0 0 0" />
    <parent
      link="base_link" />
    <child
      link="TP1" />
    <axis
      xyz="0 1 0" />
    <limit
      lower="0"
      upper="0"
      effort="0"
      velocity="0" />
  </joint>
  <link
    name="TP2">
    <inertial>
      <origin
        xyz="0.17142 0.086225 0.0015789"
        rpy="0 0 0" />
      <mass
        value="8" />
      <inertia
        ixx="1197.4"
        ixy="75.897"
        ixz="-0.9722"
        iyy="5296.7"
        iyz="-1.196"
        izz="4747.4" />
    </inertial>
    <visual>
      <origin
        xyz="0 0 0"
        rpy="0 0 0" />
      <geometry>
        <mesh
          filename="package://tractor/meshes/TP2.STL" />
      </geometry>
      <material
        name="">
        <color
          rgba="1 1 1 1" />
      </material>
    </visual>
    <collision>
      <origin
        xyz="0 0 0"
        rpy="0 0 0" />
      <geometry>
        <mesh
          filename="package://tractor/meshes/TP2.STL" />
      </geometry>
    </collision>
  </link>
  <joint
    name="tp2"
    type="prismatic">
    <origin
      xyz="-0.10254 -0.010158 0.057477"
      rpy="1.5708 -0.51088 3.1416" />
    <parent
      link="TP1" />
    <child
      link="TP2" />
    <axis
      xyz="1 0 0" />
    <limit
      lower="0"
      upper="0"
      effort="0"
      velocity="0" />
  </joint>
  <link
    name="TP3">
    <inertial>
      <origin
        xyz="0.17142 0.086225 0.0015789"
        rpy="0 0 0" />
      <mass
        value="210" />
      <inertia
        ixx="1197.4"
        ixy="75.897"
        ixz="-0.9722"
        iyy="5296.7"
        iyz="-1.196"
        izz="4747.4" />
    </inertial>
    <visual>
      <origin
        xyz="0 0 0"
        rpy="0 0 0" />
      <geometry>
        <mesh
          filename="package://tractor/meshes/TP3.STL" />
      </geometry>
      <material
        name="">
        <color
          rgba="0.75294 0.75294 0.75294 1" />
      </material>
    </visual>
    <collision>
      <origin
        xyz="0 0 0"
        rpy="0 0 0" />
      <geometry>
        <mesh
          filename="package://tractor/meshes/TP3.STL" />
      </geometry>
    </collision>
  </link>
  <joint
    name="tp3"
    type="revolute">
    <origin
      xyz="0.45756 0 0.010158"
      rpy="1.5708 0 2.6307" />
    <parent
      link="TP2" />
    <child
      link="TP3" />
    <axis
      xyz="0 1 0" />
    <limit
      lower="0"
      upper="0"
      effort="0"
      velocity="0" />
  </joint>
</robot>