<?xml version="1.0" encoding="utf-8"?>
<!-- This URDF was automatically created by SolidWorks to URDF Exporter! Originally created by Stephen Brawner (brawner@gmail.com) 
     Commit Version: 1.6.0-4-g7f85cfe  Build Version: 1.6.7995.38578
     For more information, please see http://wiki.ros.org/sw_urdf_exporter -->
<robot
  name="tractor">
  <link
    name="base_link">
    <inertial>
      <origin
        xyz="-0.2755 0.11342 0.001141"
        rpy="0 0 0" />
      <mass
        value="3290" />
      <inertia
        ixx="1181.5"
        ixy="62.869"
        ixz="-8.3091"
        iyy="4421.1"
        iyz="-0.51188"
        izz="3804.1" />
    </inertial>
    <visual>
      <origin
        xyz="0 0 0"
        rpy="0 0 0" />
      <geometry>
        <mesh
          filename="package://tractor/meshes/base_link.STL" />
      </geometry>
      <material
        name="">
        <color
          rgba="1 0.94902 0.9098 1" />
      </material>
    </visual>
    <collision>
      <origin
        xyz="0 0 0"
        rpy="0 0 0" />
      <geometry>
        <mesh
          filename="package://tractor/meshes/base_link.STL" />
      </geometry>
    </collision>
  </link>
  <joint
    name="Rear2"
    type="continuous">
    <origin
      xyz="-0.65 -0.77 0.055"
      rpy="-1.5708 0 0" />
    <parent
      link="base_link" />
    <child
      link="REAR_R" />
    <axis
      xyz="0 0 1" />
    <limit
      lower="0"
      upper="0"
      effort="0"
      velocity="0" />
  </joint>
  <link
    name="FRONT_L">
    <inertial>
      <origin
        xyz="-0.2755 0.11342 0.001141"
        rpy="0 0 0" />
      <mass
        value="3290" />
      <inertia
        ixx="1181.5"
        ixy="62.869"
        ixz="-8.3091"
        iyy="4421.1"
        iyz="-0.51188"
        izz="3804.1" />
    </inertial>
    <visual>
      <origin
        xyz="0 0 0"
        rpy="0 0 0" />
      <geometry>
        <mesh
          filename="package://tractor/meshes/FRONT_L.STL" />
      </geometry>
      <material
        name="">
        <color
          rgba="0.79216 0.81961 0.93333 1" />
      </material>
    </visual>
    <collision>
      <origin
        xyz="0 0 0"
        rpy="0 0 0" />
      <geometry>
        <mesh
          filename="package://tractor/meshes/FRONT_L.STL" />
      </geometry>
    </collision>
  </link>
  <joint
    name="Front1"
    type="continuous">
    <origin
      xyz="1.6143 0.81922 -0.13999"
      rpy="-1.5708 0 0" />
    <parent
      link="base_link" />
    <child
      link="FRONT_L" />
    <axis
      xyz="0 0 -1" />
    <limit
      lower="0"
      upper="0"
      effort="0"
      velocity="0" />
  </joint>
  <link
    name="FRONT_R">
    <inertial>
      <origin
        xyz="-0.2755 0.11342 0.001141"
        rpy="0 0 0" />
      <mass
        value="3290" />
      <inertia
        ixx="1181.5"
        ixy="62.869"
        ixz="-8.3091"
        iyy="4421.1"
        iyz="-0.51188"
        izz="3804.1" />
    </inertial>
    <visual>
      <origin
        xyz="0 0 0"
        rpy="0 0 0" />
      <geometry>
        <mesh
          filename="package://tractor/meshes/FRONT_R.STL" />
      </geometry>
      <material
        name="">
        <color
          rgba="0.79216 0.81961 0.93333 1" />
      </material>
    </visual>
    <collision>
      <origin
        xyz="0 0 0"
        rpy="0 0 0" />
      <geometry>
        <mesh
          filename="package://tractor/meshes/FRONT_R.STL" />
      </geometry>
    </collision>
  </link>
  <joint
    name="Front2"
    type="continuous">
    <origin
      xyz="1.6143 -0.81922 -0.13999"
      rpy="-1.5708 0 0" />
    <parent
      link="base_link" />
    <child
      link="FRONT_R" />
    <axis
      xyz="0 0 1" />
    <limit
      lower="0"
      upper="0"
      effort="0"
      velocity="0" />
  </joint>
  <link
    name="REAR_L">
    <inertial>
      <origin
        xyz="-0.2755 0.11342 0.001141"
        rpy="0 0 0" />
      <mass
        value="3290" />
      <inertia
        ixx="1181.5"
        ixy="62.869"
        ixz="-8.3091"
        iyy="4421.1"
        iyz="-0.51188"
        izz="3804.1" />
    </inertial>
    <visual>
      <origin
        xyz="0 0 0"
        rpy="0 0 0" />
      <geometry>
        <mesh
          filename="package://tractor/meshes/REAR_L.STL" />
      </geometry>
      <material
        name="">
        <color
          rgba="0.79216 0.81961 0.93333 1" />
      </material>
    </visual>
    <collision>
      <origin
        xyz="0 0 0"
        rpy="0 0 0" />
      <geometry>
        <mesh
          filename="package://tractor/meshes/REAR_L.STL" />
      </geometry>
    </collision>
  </link>
  <joint
    name="Rear1"
    type="continuous">
    <origin
      xyz="-0.65 0.77 0.055"
      rpy="-1.5708 0 0" />
    <parent
      link="base_link" />
    <child
      link="REAR_L" />
    <axis
      xyz="0 0 -1" />
    <limit
      lower="0"
      upper="0"
      effort="0"
      velocity="0" />
  </joint>
  <link
    name="REAR_R">
    <inertial>
      <origin
        xyz="0 0 0"
        rpy="0 0 0" />
      <mass
        value="0" />
      <inertia
        ixx="0"
        ixy="0"
        ixz="0"
        iyy="0"
        iyz="0"
        izz="0" />
    </inertial>
    <visual>
      <origin
        xyz="0 0 0"
        rpy="0 0 0" />
      <geometry>
        <mesh
          filename="package://tractor/meshes/REAR_R.STL" />
      </geometry>
      <material
        name="">
        <color
          rgba="1 1 1 1" />
      </material>
    </visual>
    <collision>
      <origin
        xyz="0 0 0"
        rpy="0 0 0" />
      <geometry>
        <mesh
          filename="package://tractor/meshes/REAR_R.STL" />
      </geometry>
    </collision>
  </link>
  <joint
    name="Rear2"
    type="continuous">
    <origin
      xyz="-0.65 -0.77 0.055"
      rpy="-1.5708 0 0" />
    <parent
      link="base_link" />
    <child
      link="REAR_R" />
    <axis
      xyz="0 0 1" />
    <limit
      lower="0"
      upper="0"
      effort="0"
      velocity="0" />
  </joint>

    <transmission name="FRONT_L">
      <type>transmission_interface/SimpleTransmission</type>
      <joint name="Front1_continuous">
      <hardwareInterface>hardware_interface/PositionJointInterface</hardwareInterface>
      </joint>
      <actuator name="Front1_motor">
      <hardwareInterface>hardware_interface/PositionJointInterface</hardwareInterface>
      <mechanicalReduction>1</mechanicalReduction>
      </actuator>
  </transmission>

  <transmission name="FRONT_R">
      <type>transmission_interface/SimpleTransmission</type>
      <joint name="Front2_continuous">
      <hardwareInterface>hardware_interface/PositionJointInterface</hardwareInterface>
      </joint>
      <actuator name="Front2_motor">
      <hardwareInterface>hardware_interface/PositionJointInterface</hardwareInterface>
      <mechanicalReduction>1</mechanicalReduction>
      </actuator>
  </transmission>

  <transmission name="REAR_L">
      <type>transmission_interface/SimpleTransmission</type>
      <joint name="Rear1_continuous">
      <hardwareInterface>hardware_interface/PositionJointInterface</hardwareInterface>
      </joint>
      <actuator name="Rear1_motor">
      <hardwareInterface>hardware_interface/PositionJointInterface</hardwareInterface>
      <mechanicalReduction>1</mechanicalReduction>
      </actuator>
  </transmission>

  <transmission name="REAR_R">
      <type>transmission_interface/SimpleTransmission</type>
      <joint name="Rear2_continuous">
      <hardwareInterface>hardware_interface/PositionJointInterface</hardwareInterface>
      </joint>
      <actuator name="Rear2_motor">
      <hardwareInterface>hardware_interface/PositionJointInterface</hardwareInterface>
      <mechanicalReduction>1</mechanicalReduction>
      </actuator>
  </transmission>

  <gazebo>
      <plugin name="gazebo_ros_control" filename="libgazebo_ros_control.so">
              <robotNamespace>/</robotNamespace>
      </plugin>
  </gazebo>

  <gazebo reference="FRONT_L">
        <selfCollide>true</selfCollide>
  </gazebo>

  <gazebo reference="FRONT_R">
        <selfCollide>true</selfCollide>
  </gazebo> 

  <gazebo reference="REAR_L">
        <selfCollide>true</selfCollide>
  </gazebo>

  <gazebo reference="REAR_R">
        <selfCollide>true</selfCollide>
  </gazebo>

</robot>
